data/online_replay/goog_lobster_replay.csv
timestamp,event_type,order_id,side,type,price,quantity
34200154,order,16155653,Buy,Limit,579,100
34200202,order,4773921,Sell,Limit,580,25
34200207,order,16167456,Sell,Limit,579,1
34200208,order,16167632,Buy,Limit,579,99
34200502,order,16228038,Sell,Limit,580,100
34200502,order,16228180,Sell,Limit,580,10
34200633,order,16252843,Buy,Limit,579,100
34200764,order,16274753,Sell,Limit,580,100
34202473,order,16477262,Sell,Limit,580,100
34202473,order,16477281,Sell,Limit,580,100
34204320,order,16654914,Sell,Limit,580,100
34204321,order,16654928,Sell,Limit,580,100
34204636,order,16680220,Sell,Limit,580,2300
34204636,order,16680228,Sell,Limit,580,400
34206027,order,16805354,Buy,Limit,579,28
34206027,order,16805379,Buy,Limit,579,78
34206028,order,16805526,Buy,Limit,579,22
34206029,order,16805605,Buy,Limit,579,4
34206030,order,16805645,Buy,Limit,579,6
34206030,order,16805664,Buy,Limit,579,7
34206030,order,16805675,Buy,Limit,579,10
34206031,order,16805696,Buy,Limit,579,9
34206031,order,16805716,Buy,Limit,579,24
34206391,order,16822527,Sell,Limit,580,260
34206393,order,16822681,Sell,Limit,580,260
34206395,order,16822749,Sell,Limit,580,260
34206397,order,16822847,Sell,Limit,580,260
34206399,order,16822977,Sell,Limit,580,260
34206401,order,16823104,Sell,Limit,580,260
34206403,order,16823214,Sell,Limit,580,260
34206406,order,16823323,Sell,Limit,580,260
34206408,order,16823470,Sell,Limit,580,260
34206410,order,16823634,Sell,Limit,580,260
34206412,order,16823779,Sell,Limit,580,260
34206414,order,16823945,Sell,Limit,580,260
34207657,order,16883952,Sell,Limit,580,260
34207660,order,16884073,Sell,Limit,580,260
34207663,order,16884221,Sell,Limit,580,260
34207665,order,16884363,Sell,Limit,580,260
34207668,order,16884483,Sell,Limit,580,260
34207670,order,16884674,Sell,Limit,580,260
34207674,order,16885333,Sell,Limit,580,260
34207676,order,16885580,Sell,Limit,580,260
34207679,order,16885653,Sell,Limit,580,260
34207681,order,16885764,Sell,Limit,580,260
34207684,order,16885944,Sell,Limit,580,260
34207687,order,16886066,Sell,Limit,580,260
34207689,order,16886214,Sell,Limit,580,260
34207692,order,16886286,Sell,Limit,580,260
34207695,order,16886468,Sell,Limit,580,260
34207698,order,16886587,Sell,Limit,580,260
34208146,order,16903596,Sell,Limit,580,2
34208146,order,16903615,Sell,Limit,580,2
34209135,order,16936717,Sell,Limit,579,100
34209153,order,16937480,Sell,Limit,579,2
34209745,order,16955579,Sell,Limit,579,10
34210172,order,16981526,Sell,Limit,579,19
34210740,order,17020275,Sell,Limit,579,100
34212150,order,17083481,Sell,Limit,579,2171
34212172,order,17085000,Sell,Limit,579,2171
34212205,order,17086852,Sell,Limit,578,1278
34212205,order,17086865,Sell,Limit,578,400
34212206,order,17086988,Buy,Limit,578,200
34212208,order,17087159,Sell,Limit,578,578
34212247,order,17089209,Buy,Limit,578,66
34212247,order,17089214,Sell,Limit,578,102
34212277,order,17090451,Sell,Limit,578,2
34212295,order,17091418,Sell,Limit,578,2
34212296,order,17091434,Buy,Limit,578,98
34212318,order,17092219,Sell,Limit,579,100
34212343,order,17093146,Sell,Limit,579,2
34212720,order,17104353,Buy,Limit,577,100
34212725,order,17104451,Buy,Limit,577,8
34213294,order,17120812,Buy,Limit,577,600
34215472,order,17185218,Sell,Limit,579,100
34215472,order,17185233,Sell,Limit,579,100
34216116,order,17206828,Buy,Limit,578,600
34217148,order,17247457,Sell,Limit,578,100
34217148,order,17247479,Sell,Limit,578,100
34217168,order,17248228,Sell,Limit,578,100
34217168,order,17248243,Sell,Limit,578,100
34218873,order,17309383,Sell,Limit,578,100
34218876,order,17309581,Buy,Limit,578,600
34218876,order,17309594,Sell,Limit,578,100
34218876,order,17309609,Sell,Limit,578,200
34218876,order,17309618,Sell,Limit,578,100
34218876,order,17309623,Sell,Limit,578,100
34218876,order,17309668,Sell,Limit,578,100
34218877,order,17309710,Sell,Limit,578,100
34218993,order,17313565,Sell,Limit,578,100
34218993,order,17313572,Sell,Limit,578,100
34218994,order,17313580,Sell,Limit,578,100
34219844,order,17345366,Buy,Limit,578,100
34219844,order,17345369,Sell,Limit,578,100
34220034,order,17350896,Sell,Limit,578,10
34220034,order,17350910,Sell,Limit,578,100
34221016,order,17381731,Buy,Limit,578,100
34221122,order,17386271,Buy,Limit,578,140
34221125,order,17386739,Buy,Limit,578,140
34222151,order,17416529,Sell,Limit,578,100
34222390,order,17425290,Buy,Limit,578,100
34222837,order,17437777,Buy,Limit,578,600
34223681,order,17461889,Sell,Limit,578,75
34224448,order,17480645,Buy,Limit,578,200
34225669,order,17516942,Buy,Limit,578,300
34226583,order,17538298,Buy,Limit,578,600
34227031,order,17549203,Buy,Limit,578,100
34227611,order,17575633,Buy,Limit,578,100
34227627,order,17579487,Buy,Limit,578,100
34227628,order,17579715,Sell,Limit,579,120
34227628,order,17579731,Sell,Limit,579,100
34227641,order,17581238,Buy,Limit,578,100
34227644,order,17581549,Buy,Limit,578,100
34227648,order,17582033,Sell,Limit,579,100
34227649,order,17582051,Buy,Limit,578,100
34227650,order,17582212,Sell,Limit,579,100
34227652,order,17582366,Sell,Limit,579,120
34227652,order,17582374,Buy,Limit,578,100
34227653,order,17582542,Sell,Limit,579,100
34227653,order,17582562,Sell,Limit,579,100
34227654,order,17582644,Buy,Limit,578,100
34227655,order,17582785,Sell,Limit,579,100
34227657,order,17582911,Sell,Limit,579,120
34227657,order,17582915,Buy,Limit,578,100
34227661,order,17583338,Sell,Limit,579,100
34227661,order,17583346,Buy,Limit,578,100
34227662,order,17583434,Sell,Limit,579,100
34227664,order,17583543,Buy,Limit,578,100
34227664,order,17583549,Sell,Limit,579,120
34227665,order,17583661,Sell,Limit,579,100
34227665,order,17583678,Sell,Limit,579,100
34227666,order,17583765,Buy,Limit,578,100
34227668,order,17583879,Sell,Limit,579,100
34227669,order,17583992,Sell,Limit,579,120
34227669,order,17583996,Buy,Limit,578,100
34227670,order,17584117,Sell,Limit,579,100
34227672,order,17584230,Sell,Limit,579,120
34227672,order,17584231,Buy,Limit,578,100
34227673,order,17584309,Sell,Limit,579,100
34227675,order,17584414,Buy,Limit,578,100
34227675,order,17584416,Sell,Limit,579,120
34227694,order,17585736,Sell,Limit,579,105
34227694,order,17585740,Buy,Limit,578,100
34227694,order,17585743,Sell,Limit,579,100
34227697,order,17585881,Sell,Limit,579,100
34227697,order,17585885,Buy,Limit,578,100
34227698,order,17585962,Sell,Limit,579,100
34227699,order,17586043,Buy,Limit,578,100
34227700,order,17586129,Sell,Limit,579,100
34227702,order,17586226,Sell,Limit,579,120
34227702,order,17586237,Buy,Limit,578,100
34227703,order,17586346,Sell,Limit,579,100
34227704,order,17586463,Sell,Limit,579,120
34227704,order,17586471,Buy,Limit,578,100
34227705,order,17586593,Sell,Limit,579,100
34227706,order,17586702,Sell,Limit,579,120
34227706,order,17586711,Buy,Limit,578,100
34227707,order,17586721,Sell,Limit,579,100
34227709,order,17587029,Sell,Limit,579,100
34227709,order,17587046,Buy,Limit,578,100
34227715,order,17587601,Sell,Limit,579,100
34227715,order,17587603,Buy,Limit,578,100
34227718,order,17587881,Buy,Limit,578,100
34227719,order,17588298,Sell,Limit,579,100
34227719,order,17588370,Sell,Limit,579,100
34227720,order,17588850,Sell,Limit,579,120
34227720,order,17588936,Buy,Limit,578,100
34227720,order,17588977,Sell,Limit,579,100
34227721,order,17589524,Buy,Limit,578,100
34227723,order,17590213,Sell,Limit,579,120
34227723,order,17590245,Buy,Limit,578,100
34227727,order,17591196,Sell,Limit,579,100
34227729,order,17591764,Buy,Limit,578,100
34227729,order,17591766,Sell,Limit,579,100
34227731,order,17592550,Buy,Limit,578,100
34227731,order,17592559,Sell,Limit,579,105
34227962,order,17622086,Buy,Limit,579,200
34228330,order,17644180,Sell,Limit,580,100
34228330,order,17644185,Sell,Limit,580,100
34228338,order,17644440,Sell,Limit,580,100
34228340,order,17644490,Sell,Limit,580,100
34228342,order,17644584,Sell,Limit,580,100
34228343,order,17644588,Sell,Limit,580,100
34228345,order,17644718,Sell,Limit,580,100
34228347,order,17644817,Sell,Limit,580,100
34228350,order,17644881,Sell,Limit,580,100
34228353,order,17644956,Sell,Limit,580,100
